<?xml version="1.0" ?>
<robot name="nuri_wheelchair"
  xmlns:xacro="http://ros.org/wiki/xacro">
	<material name="dark">
		<color rgba="0 0.1 0.1 0.2"/>
	</material>
	<material name="dark1">
		<color rgba="0 0.1 0.1 0.1"/>
	</material>
	<material name="dark2">
		<color rgba="0 0.2 0.2 0.2"/>
	</material>
	<link name="base_footprint" />
	<link name="base_link">
		<visual>
			<origin xyz="0 0 0" rpy="0 0 0"/>
			<geometry>
				<box size="0.05 0.05 0.05"/>
			</geometry>
          	<material name="dark"/>
		</visual>  
	</link>
	<joint name="base_joint" type="fixed">
		<parent link="base_footprint"/>
		<child link="base_link" />
		<origin xyz="0 0 0" rpy="0 0 0"/>
	</joint>
	<link name="housing_link">
		<visual>
			<origin xyz="0 0 0" rpy="0 0 0"/>
			<geometry>
				<box size="0.5 0.43 0.40"/>
			</geometry>
			<material name="dark2"/>
		</visual>
		<collision>
			<origin xyz="0 0 0" rpy="0 0 0"/>
			<geometry>
				<box size="0.5 0.45 0.02"/>
			</geometry>
		</collision>
	</link>
	<joint name="housing_joint" type="fixed">
		<parent link="base_link"/>
		<child link="housing_link" />
		<origin xyz="0.2 0 0.2" rpy="0 0 0.0"/>
	</joint>
	<link name="wheel_left_link">
		<visual>
			<origin xyz="0 0 0" rpy="0 0 0"/>
			<geometry>
				<box size="0.6 0.02 0.6"/>
			</geometry>
			<material name="dark"/>
		</visual>
		<collision>
			<origin xyz="0 0 0" rpy="0 0 0"/>
			<geometry>
				<box size="0.6 0.05 0.6"/>
			</geometry>
		</collision>
	</link>
	<joint name="wheel_left_joint" type="continuous">
		<parent link="base_link"/>
		<child link="wheel_left_link"/>
		<origin xyz="0 0.225 0.3" rpy="0 0 0"/>
	</joint>
	<link name="wheel_right_link">
		<visual>
			<origin xyz="0 0 0" rpy="0 0 0"/>
			<geometry>
				<box size="0.6 0.02 0.6"/>
			</geometry>
			<material name="dark"/>
		</visual>
		<collision>
			<origin xyz="0 0 0" rpy="0 0 0"/>
			<geometry>
				<box size="0.6 0.05 0.6"/>
			</geometry>
		</collision>
	</link>
	<joint name="wheel_right_joint" type="continuous">
		<parent link="base_link"/>
		<child link="wheel_right_link"/>
		<origin xyz="0 -0.225 0.3" rpy="0 0 0"/>
	</joint>
	<link name="base_scan">
		<visual>
			<origin xyz="0 0 -0.046" rpy="0 0 0"/>
			<geometry>
				<box size="0.052 0.052 0.03"/>
			</geometry>
			<material name="dark"/>
		</visual>
		<collision>
			<origin xyz="0 0 -0.046" rpy="0 0 0"/>
			<geometry>
				<box size="0.1 0.1 0.1"/>
			</geometry>
		</collision>
	</link>
	<joint name="scan_joint" type="fixed">
		<parent link="base_link"/>
		<child link="base_scan"/>
		<origin xyz="0.46 0.225 0.58" rpy="0 0 0"/>
	</joint>
	<link name="sonar_sensor_front_left">
		<visual>
          <origin xyz="0 0 0" rpy="0 0 0"/>
          <geometry>
            <cylinder length="0.02" radius="0.01"/>
          </geometry>
          <material name="dark2"/>
		</visual>
		<collision>
          <origin xyz="0 0 0" rpy="0 0 0"/>
          <geometry>
            <cylinder length="0.02" radius="0.01"/>
          </geometry>
		</collision>
	</link>
	<joint name="sonar_sensor_front_left_joint" type="fixed">
		<parent link="base_link"/>
		<child link="sonar_sensor_front_left"/>
      	<origin xyz="0.5 0.2 0.51" rpy="0 1.5708 0"/>
	</joint>
	<link name="sonar_sensor_left">
		<visual>
          <origin xyz="0 0 0" rpy="0 0 0"/>
          <geometry>
            <cylinder length="0.02" radius="0.01"/>
          </geometry>
          <material name="dark2"/>
		</visual>
		<collision>
          <origin xyz="0 0 0" rpy="0 0 0"/>
          <geometry>
            <cylinder length="0.02" radius="0.01"/>
          </geometry>
		</collision>
	</link>
	<joint name="sonar_sensor_left_joint" type="fixed">
		<parent link="base_link"/>
		<child link="sonar_sensor_left"/>
      	<origin xyz="0.5 0.25 0.51" rpy="1.5708 0 0"/>
	</joint>
	<link name="sonar_sensor_front_right">
		<visual>
          <origin xyz="0 0 0" rpy="0 0 0"/>
          <geometry>
            <cylinder length="0.02" radius="0.01"/>
          </geometry>
          <material name="dark2"/>
		</visual>
		<collision>
          <origin xyz="0 0 0" rpy="0 0 0"/>
          <geometry>
            <cylinder length="0.02" radius="0.01"/>
          </geometry>
		</collision>
	</link>
	<joint name="sonar_sensor_front_right_joint" type="fixed">
		<parent link="base_link"/>
		<child link="sonar_sensor_front_right"/>
      	<origin xyz="0.5 -0.2 0.51" rpy="0 1.5708 0"/>
	</joint>
	<link name="sonar_sensor_right">
		<visual>
          <origin xyz="0 0 0" rpy="0 0 0"/>
          <geometry>
            <cylinder length="0.02" radius="0.01"/>
          </geometry>
          <material name="dark2"/>
		</visual>
		<collision>
          <origin xyz="0 0 0" rpy="0 0 0"/>
          <geometry>
            <cylinder length="0.02" radius="0.01"/>
          </geometry>
		</collision>
	</link>
	<joint name="sonar_sensor_right_joint" type="fixed">
		<parent link="base_link"/>
		<child link="sonar_sensor_right"/>
      	<origin xyz="0.5 -0.25 0.51" rpy="1.5708 0 0"/>
	</joint>
	<link name="sonar_sensor_back">
		<visual>
          <origin xyz="0 0 0" rpy="0 0 0"/>
          <geometry>
            <cylinder length="0.02" radius="0.01"/>
          </geometry>
          <material name="dark2"/>
		</visual>
		<collision>
          <origin xyz="0 0 0" rpy="0 0 0"/>
          <geometry>
            <cylinder length="0.02" radius="0.01"/>
          </geometry>
		</collision>
	</link>
	<joint name="sonar_sensor_back_joint" type="fixed">
		<parent link="base_link"/>
		<child link="sonar_sensor_back"/>
      	<origin xyz="-0.28 0 0.28" rpy="0 0 1.5708"/>
	</joint>
	<link name="imu_link" />	
	<joint name="imu_joint" type="fixed">
		<parent link="base_link"/>
		<child link="imu_link"/>
		<origin xyz="-0.2 0.045 0.47" rpy="0 0 0"/>
	</joint>
</robot>